try:
    result = 10 / 0
finally:
    print("This is printed after the exception")
